如果作为参数的 Promise 实例，自己定义了catch方法，那么它一旦被rejected，并不会触发Promise.all()的catch方法。

ChatGPT

确实，当你在使用 `Promise.all()` 时，如果其中的某个 Promise 已经通过其自己的 `.catch()` 方法处理了拒绝（rejected）状态，那么这个错误不会传递到 `Promise.all()` 的 `.catch()` 方法中。这是因为 `Promise.all()` 只处理那些未被捕获的拒绝状态。如果一个 Promise 的错误已经被捕获并处理，那么从 `Promise.all()` 的角度看，这个 Promise 被认为是已成功解决的。

### 示例和解释

假设你有两个 Promise，其中一个已经定义了自己的 `.catch()` 方法来捕获错误，另一个没有。这里是一个简单的示例：

```
javascript复制代码const promise1 = new Promise((resolve, reject) => {
  reject("Error in promise1");
}).catch(err => {
  console.log("Caught in promise1:", err);
  return "Handled by promise1";
});

const promise2 = new Promise((resolve, reject) => {
  reject("Error in promise2");
});

Promise.all([promise1, promise2])
  .then(results => {
    console.log("Promise.all resolved with:", results);
  })
  .catch(err => {
    console.log("Caught by Promise.all:", err);
  });
```

在这个例子中：

- `promise1` 处理了自己的错误，并且返回了一个新的值（"Handled by promise1"），因此对 `Promise.all()` 来说，它被视为已成功解决。
- `promise2` 没有捕获其错误，所以它的拒绝会被 `Promise.all()` 的 `.catch()` 捕获。

### 输出

```
javascript复制代码Caught in promise1: Error in promise1
Caught by Promise.all: Error in promise2
```

`Promise.all()` 不会输出 `promise1` 的错误，因为它已经被 `promise1` 内部的 `.catch()` 处理了。

### 如何确保错误被 `Promise.all()` 捕获

如果你希望即使在单个 Promise 中捕获了错误之后，这个错误仍能影响到 `Promise.all()` 的结果，你可以在捕获错误后重新抛出它：

```
javascript复制代码const promise1 = new Promise((resolve, reject) => {
  reject("Error in promise1");
}).catch(err => {
  console.log("Caught in promise1:", err);
  throw err; // Re-throw the error to make it propagate
});
```

这样，即使错误在 `promise1` 中被捕获，`Promise.all()` 也会因为这个重新抛出的错误而被拒绝。

### 结论

这种行为有助于更细粒度地控制错误处理逻辑，允许你在适当的层级处理错误，同时提供了向上抛出错误以处理更全局问题的能力。在设计使用多个 Promise 的程序时，了解这一点非常重要，以确保错误处理逻辑符合你的应用需求。

allSettled 是否也是这样

ChatGPT

`Promise.allSettled()` 方法与 `Promise.all()` 方法的行为有所不同，它会等待所有 Promise 解决（无论是成功还是失败），然后返回一个包含每个 Promise 结果的数组，每个结果都是一个对象，包含 `status` 字段和 `value` 或 `reason` 字段。因此，即使某个 Promise 已经通过其自己的 `.catch()` 方法处理了拒绝状态，它的结果仍然会包含在 `Promise.allSettled()` 的返回数组中。

下面是一个简单的示例来说明这一点：

```
javascript复制代码const promise1 = Promise.resolve("Resolved value from promise1");
const promise2 = Promise.reject("Error from promise2").catch(err => {
  console.log("Caught in promise2:", err);
  return "Handled by promise2";
});

Promise.allSettled([promise1, promise2])
  .then(results => {
    console.log("Promise.allSettled results:", results);
  })
  .catch(err => {
    console.log("Caught by Promise.allSettled:", err);
  });
```

在这个示例中，`promise1` 是一个解决的 Promise，而 `promise2` 是一个被拒绝的 Promise，并且已经在自己的 `.catch()` 方法中处理了错误。即使 `promise2` 的错误已经被处理，它仍然会出现在 `Promise.allSettled()` 返回的结果中。

### 输出

```
css复制代码Caught in promise2: Error from promise2
Promise.allSettled results: [
  { status: 'fulfilled', value: 'Resolved value from promise1' },
  { status: 'fulfilled', value: 'Handled by promise2' }
]
```

如你所见，即使 `promise2` 的错误已被捕获和处理，它仍然作为一个已解决的 Promise 出现在了 `Promise.allSettled()` 的结果中。这与 `Promise.all()` 不同，后者只会处理那些未被捕获的 Promise 的拒绝状态。

如果一个 promise ，promise1，promise1.then(,()=>{}) fulfilled的状态，赢不赢他的返回，就是缺少fulfilled 处理函数的情况

ChatGPT

当你对一个 Promise 使用 `.then()` 方法，并且只提供了拒绝（rejected）状态的处理函数，而没有为解决（fulfilled）状态提供处理函数时，该 Promise 的解决值将“穿透”这个 `.then()` 调用，直到遇到一个提供了处理函数的 `.then()` 或 `.catch()`。这就是所谓的 Promise“穿透”或“传递”行为。

### 解释和示例

假设我们有一个 Promise `promise1`，它最终被解决（fulfilled）。如果我们在调用 `.then()` 时没有提供处理解决状态的函数，这个解决值会被传递到链中的下一个处理函数：

```
javascript复制代码const promise1 = Promise.resolve("Success!");

promise1
  .then(null, () => {
    console.log("This won't be called because the promise was fulfilled.");
  })
  .then(result => {
    console.log("Received in the next then:", result);
  });
```

在这个例子中，`promise1` 是一个解决为 `"Success!"` 的 Promise。第一个 `.then()` 方法提供了 `null` 作为解决状态的处理函数（表示不处理解决状态），并且提供了一个函数来处理拒绝状态（这个函数不会被调用，因为 Promise 是解决的）。由于没有处理解决状态的函数，解决值 `"Success!"` 将被传递到下一个 `.then()`，在那里它被输出。

### 总结

- **Promise 穿透**：当 `.then()` 或 `.catch()` 没有提供相应的处理函数时，Promise 的状态和值会穿透到下一个相应的处理器。
- **处理函数缺失**：如果 `.then()` 缺少解决处理函数，解决值会传递到链中的下一个解决处理函数。类似地，如果 `.then()` 或 `.catch()` 缺少拒绝处理函数，拒绝的原因将会传递到链中的下一个拒绝处理函数。

这种行为使得 Promise 链更加灵活，允许开发者只在需要时处理特定状态，或者在链的末尾统一处理错误。

把这个翻译成英文

ChatGPT

When you use the `.then()` method on a Promise and only provide a rejection handler without providing a fulfillment handler, the fulfillment value of the Promise will "pass through" this `.then()` call until it reaches a `.then()` or `.catch()` that provides a handler. This is referred to as Promise "pass-through" or "propagation" behavior.

### Explanation and Example

Suppose we have a Promise `promise1` that ultimately fulfills. If we call `.then()` without providing a fulfillment handler, the fulfillment value will be passed to the next handler in the chain:

```
javascript复制代码const promise1 = Promise.resolve("Success!");

promise1
  .then(null, () => {
    console.log("This won't be called because the promise was fulfilled.");
  })
  .then(result => {
    console.log("Received in the next then:", result);
  });
```

In this example, `promise1` is a Promise resolved with "Success!". The first `.then()` method provides `null` as the fulfillment handler (indicating no handling of the fulfilled state) and a function to handle the rejection state (which will not be called because the Promise is fulfilled). Since there is no handler for the fulfilled state, the resolved value "Success!" is passed to the next `.then()`, where it is logged.

### Summary

- **Promise Propagation**: When a `.then()` or `.catch()` lacks the corresponding handler, the state and value of the Promise will propagate to the next appropriate handler in the chain.
- **Missing Handler**: If `.then()` lacks a fulfillment handler, the resolved value will pass to the next fulfillment handler in the chain. Similarly, if a `.then()` or `.catch()` lacks a rejection handler, the reason for rejection will pass to the next rejection handler in the chain.

This behavior allows for greater flexibility in Promise chains, enabling developers to handle specific states only when necessary, or to uniformly handle errors at the end of the chain.

布尔值为 false 是否可以代替 null

ChatGPT

在 JavaScript 中，使用 `false` 代替 `null` 在 `.then()` 方法的参数中可能会导致不同的行为，这取决于你的使用场景和预期结果。在 Promise 的 `.then()` 方法中，处理器参数应当是一个函数或者 `null`。如果传递了 `false` 或其他非函数值，这些值会被忽略，并且会导致 Promise 的解决或拒绝值直接传递到下一个 `.then()`，类似于传递 `null` 的行为。

### 使用 `false` 替代 `null`

在 `.then()` 的上下文中，如果你使用 `false` 替代 `null` 作为处理器参数，这里的 `false` 不会被解释为一个函数。这会导致 `.then()` 方法忽略这个参数，解决（或拒绝）值将会“穿透”到链中的下一个 `.then()`。这实际上与提供 `null` 或省略该参数的效果相同：

```
javascript复制代码const promise1 = Promise.resolve("Success!");

promise1
  .then(false, () => {
    console.log("This won't be called because the promise was fulfilled.");
  })
  .then(result => {
    console.log("Received in the next then:", result);
  });
```

在这个例子中，`.then(false, ...)` 中的 `false` 将被忽略，因为它不是一个函数。因此，"Success!" 将被传递到下一个 `.then()`，与传递 `null` 或直接省略处理器会产生相同的结果。

### 结论

虽然在技术上使用 `false` 代替 `null` 在很多情况下行为看似相似，因为非函数值在处理器位置会被忽略，但这种做法在语义上可能引起混淆。在编写清晰可维护的代码时，建议明确使用 `null` 来表示你有意省略了特定的处理器，这可以提高代码的可读性和意图的清晰性。使用 `null` 是更标准和明确的方式，表明没有为特定的状态提供处理函数。

布尔值为 false 的值呢，例如 undefined

ChatGPT

在 JavaScript 的 `Promise.then()` 方法中使用 `undefined` 与使用 `false` 或 `null` 来代替函数参数具有相似的行为。任何非函数值，包括 `undefined`、`false` 和 `null`，当用作 `then()` 或 `catch()` 的参数时，都会导致 Promise 解决值或拒绝原因的“穿透”。这意味着，如果处理函数不是有效的函数，则这些值将不会被处理，而是直接传递到 Promise 链中的下一个处理器。

### 示例

下面的例子演示了当 `then()` 方法中的成功处理函数被设置为 `undefined` 时的行为：

```
javascript复制代码const promise1 = Promise.resolve("Success!");

promise1
  .then(undefined, () => {
    console.log("This won't be called because the promise was fulfilled.");
  })
  .then(result => {
    console.log("Received in the next then:", result);  // 输出: "Received in the next then: Success!"
  })
  .catch(error => {
    console.log("Caught an error:", error);
  });
```

在这个例子中：

- 第一个 `.then()` 中的成功处理函数是 `undefined`，所以它被忽略，且解决值 `"Success!"` 穿透到下一个 `.then()`。
- 第二个 `.then()` 接收到这个穿透的值并输出。

### 解释

这种行为是因为 Promise 规范定义了如何处理 `.then()` 或 `.catch()` 接收到的非函数参数。如果参数不是函数，Promise 将把前一个 Promise 的结果直接传递给链中的下一个处理器。这样的设计允许你在 Promise 链中选择性地处理你感兴趣的结果或错误，而无需在每个步骤中都提供回调函数。

### 使用建议

虽然使用 `undefined` 在 `then()` 中会导致值的穿透，这一行为在技术上是符合规范的，但在实际编程中，最好是明确地省略那些你不想处理的参数，或者使用 `null` 来提高代码的可读性。例如：

```
javascript
复制代码
promise1.then(null, errorHandler);
```

这种写法比使用 `undefined` 或其他非函数值更清晰，更明确地表达了你的意图，即你只关心错误处理。这有助于保持代码的可读性和维护性，特别是在团队协作和大型项目中。

总结来说，虽然 `undefined`、`null` 和 `false` 在这种用法中表现相似，但为了代码的清晰和一致性，最好使用 `null` 来明确表示省略了处理函数。
